Workbook

Sheet A
A1: Trial | B1: Condition | C1: TargetDist | D1: TargetAngle | E1: RespDist | F1: RespAngle | G1: ErrDist | H1: ErrAngle | I1: FBConf | J1: IsInsideHead | K1: 分析距離 | L1: 有効角度誤差 | M1: New FB
A2: sub1 1 | B2: CircularDVF_Sph_EC_Off_Corr_Off | C2: 1.5 | D2: 0 | E2: 0.9685215 | F2: -0.18334587 | G2: -0.5314785 | H2: -0.18334587 | I2: 0 | J2: 0 | K2: =IF(J2=1, "", E2) -> 0.9685215 | L2: =IF(J2=1, "", IF(D2=90, ABS(MOD(F2-D2+180, 360)-180), ABS(IF(ABS(MOD(F2-(180-D2)+180, 360)-180) < ABS(MOD(F2-D2+180, 360)-180), MOD(F2-(180-D2)+180, 360)-180, MOD(F2-D2+180, 360)-180)))) -> 0.18334587 | M2: =IF(OR(J2=1, D2=90), 0, IF(ABS(MOD(F2-(180-D2)+180, 360)-180) < ABS(MOD(F2-D2+180, 360)-180), 1, 0)) -> 0
A3: 2 | B3: CircularDVF_Sph_EC_Off_Corr_Off | C3: 1 | D3: 45 | E3: 0.99902258 | F3: 90.444374 | G3: -0.00097742405 | H3: 45.444374 | I3: 1 | J3: 0 | K3: =IF(J3=1, "", E3) -> 0.99902258 | L3: =IF(J3=1, "", IF(D3=90, ABS(MOD(F3-D3+180, 360)-180), ABS(IF(ABS(MOD(F3-(180-D3)+180, 360)-180) < ABS(MOD(F3-D3+180, 360)-180), MOD(F3-(180-D3)+180, 360)-180, MOD(F3-D3+180, 360)-180)))) -> 44.555626 | M3: =IF(OR(J3=1, D3=90), 0, IF(ABS(MOD(F3-(180-D3)+180, 360)-180) < ABS(MOD(F3-D3+180, 360)-180), 1, 0)) -> 1
A4: 3 | B4: CircularDVF_Sph_EC_Off_Corr_Off | C4: 0.5 | D4: 0 | E4: 0.96908058 | F4: 178.04506 | G4: 0.46908058 | H4: 178.04506 | I4: 1 | J4: 0 | K4: =IF(J4=1, "", E4) -> 0.96908058 | L4: =IF(J4=1, "", IF(D4=90, ABS(MOD(F4-D4+180, 360)-180), ABS(IF(ABS(MOD(F4-(180-D4)+180, 360)-180) < ABS(MOD(F4-D4+180, 360)-180), MOD(F4-(180-D4)+180, 360)-180, MOD(F4-D4+180, 360)-180)))) -> 1.954937 | M4: =IF(OR(J4=1, D4=90), 0, IF(ABS(MOD(F4-(180-D4)+180, 360)-180) < ABS(MOD(F4-D4+180, 360)-180), 1, 0)) -> 1
A5: 4 | B5: CircularDVF_Sph_EC_Off_Corr_Off | C5: 0.5 | D5: 45 | E5: 0.99939641 | F5: 91.628965 | G5: 0.49939641 | H5: 46.628965 | I5: 1 | J5: 0 | K5: =IF(J5=1, "", E5) -> 0.99939641 | L5: =IF(J5=1, "", IF(D5=90, ABS(MOD(F5-D5+180, 360)-180), ABS(IF(ABS(MOD(F5-(180-D5)+180, 360)-180) < ABS(MOD(F5-D5+180, 360)-180), MOD(F5-(180-D5)+180, 360)-180, MOD(F5-D5+180, 360)-180)))) -> 43.371035 | M5: =IF(OR(J5=1, D5=90), 0, IF(ABS(MOD(F5-(180-D5)+180, 360)-180) < ABS(MOD(F5-D5+180, 360)-180), 1, 0)) -> 1
A6: 5 | B6: CircularDVF_Sph_EC_Off_Corr_Off | C6: 0.35 | D6: 135 | E6: 1.5085703 | F6: 136.40124 | G6: 1.1585703 | H6: 1.40124 | I6: 0 | J6: 0 | K6: =IF(J6=1, "", E6) -> 1.5085703 | L6: =IF(J6=1, "", IF(D6=90, ABS(MOD(F6-D6+180, 360)-180), ABS(IF(ABS(MOD(F6-(180-D6)+180, 360)-180) < ABS(MOD(F6-D6+180, 360)-180), MOD(F6-(180-D6)+180, 360)-180, MOD(F6-D6+180, 360)-180)))) -> 1.40124 | M6: =IF(OR(J6=1, D6=90), 0, IF(ABS(MOD(F6-(180-D6)+180, 360)-180) < ABS(MOD(F6-D6+180, 360)-180), 1, 0)) -> 0
A7: 6 | B7: CircularDVF_Sph_EC_Off_Corr_Off | C7: 0.5 | D7: 0 | E7: 1.0000556 | F7: 1.8943636 | G7: 0.50005563 | H7: 1.8943636 | I7: 0 | J7: 0 | K7: =IF(J7=1, "", E7) -> 1.0000556 | L7: =IF(J7=1, "", IF(D7=90, ABS(MOD(F7-D7+180, 360)-180), ABS(IF(ABS(MOD(F7-(180-D7)+180, 360)-180) < ABS(MOD(F7-D7+180, 360)-180), MOD(F7-(180-D7)+180, 360)-180, MOD(F7-D7+180, 360)-180)))) -> 1.8943636 | M7: =IF(OR(J7=1, D7=90), 0, IF(ABS(MOD(F7-(180-D7)+180, 360)-180) < ABS(MOD(F7-D7+180, 360)-180), 1, 0)) -> 0
A8: 7 | B8: CircularDVF_Sph_EC_Off_Corr_Off | C8: 1 | D8: 0 | E8: 1.0357412 | F8: 0.68580201 | G8: 0.035741216 | H8: 0.68580201 | I8: 0 | J8: 0 | K8: =IF(J8=1, "", E8) -> 1.0357412 | L8: =IF(J8=1, "", IF(D8=90, ABS(MOD(F8-D8+180, 360)-180), ABS(IF(ABS(MOD(F8-(180-D8)+180, 360)-180) < ABS(MOD(F8-D8+180, 360)-180), MOD(F8-(180-D8)+180, 360)-180, MOD(F8-D8+180, 360)-180)))) -> 0.68580201 | M8: =IF(OR(J8=1, D8=90), 0, IF(ABS(MOD(F8-(180-D8)+180, 360)-180) < ABS(MOD(F8-D8+180, 360)-180), 1, 0)) -> 0
A9: 8 | B9: CircularDVF_Sph_EC_Off_Corr_Off | C9: 1 | D9: 0 | E9: 1.0203219 | F9: 0.9862603 | G9: 0.020321917 | H9: 0.9862603 | I9: 0 | J9: 0 | K9: =IF(J9=1, "", E9) -> 1.0203219 | L9: =IF(J9=1, "", IF(D9=90, ABS(MOD(F9-D9+180, 360)-180), ABS(IF(ABS(MOD(F9-(180-D9)+180, 360)-180) < ABS(MOD(F9-D9+180, 360)-180), MOD(F9-(180-D9)+180, 360)-180, MOD(F9-D9+180, 360)-180)))) -> 0.9862603 | M9: =IF(OR(J9=1, D9=90), 0, IF(ABS(MOD(F9-(180-D9)+180, 360)-180) < ABS(MOD(F9-D9+180, 360)-180), 1, 0)) -> 0
A10: 9 | B10: CircularDVF_Sph_EC_Off_Corr_Off | C10: 1.5 | D10: 180 | E10: 0.96859588 | F10: 179.26665 | G10: -0.53140412 | H10: -0.73334593 | I10: 0 | J10: 0 | K10: =IF(J10=1, "", E10) -> 0.96859588 | L10: =IF(J10=1, "", IF(D10=90, ABS(MOD(F10-D10+180, 360)-180), ABS(IF(ABS(MOD(F10-(180-D10)+180, 360)-180) < ABS(MOD(F10-D10+180, 360)-180), MOD(F10-(180-D10)+180, 360)-180, MOD(F10-D10+180, 360)-180)))) -> 0.73334593 | M10: =IF(OR(J10=1, D10=90), 0, IF(ABS(MOD(F10-(180-D10)+180, 360)-180) < ABS(MOD(F10-D10+180, 360)-180), 1, 0)) -> 0
A11: 10 | B11: CircularDVF_Sph_EC_Off_Corr_Off | C11: 1 | D11: 180 | E11: 1.0110065 | F11: 2.7527666 | G11: 0.011006547 | H11: -177.24723 | I11: 1 | J11: 0 | K11: =IF(J11=1, "", E11) -> 1.0110065 | L11: =IF(J11=1, "", IF(D11=90, ABS(MOD(F11-D11+180, 360)-180), ABS(IF(ABS(MOD(F11-(180-D11)+180, 360)-180) < ABS(MOD(F11-D11+180, 360)-180), MOD(F11-(180-D11)+180, 360)-180, MOD(F11-D11+180, 360)-180)))) -> 2.7527666 | M11: =IF(OR(J11=1, D11=90), 0, IF(ABS(MOD(F11-(180-D11)+180, 360)-180) < ABS(MOD(F11-D11+180, 360)-180), 1, 0)) -> 1
A12: 11 | B12: CircularDVF_Sph_EC_Off_Corr_Off | C12: 1 | D12: 135 | E12: 0.98352678 | F12: 90.451375 | G12: -0.016473215 | H12: -44.548625 | I12: 0 | J12: 0 | K12: =IF(J12=1, "", E12) -> 0.98352678 | L12: =IF(J12=1, "", IF(D12=90, ABS(MOD(F12-D12+180, 360)-180), ABS(IF(ABS(MOD(F12-(180-D12)+180, 360)-180) < ABS(MOD(F12-D12+180, 360)-180), MOD(F12-(180-D12)+180, 360)-180, MOD(F12-D12+180, 360)-180)))) -> 44.548625 | M12: =IF(OR(J12=1, D12=90), 0, IF(ABS(MOD(F12-(180-D12)+180, 360)-180) < ABS(MOD(F12-D12+180, 360)-180), 1, 0)) -> 0
A13: 12 | B13: CircularDVF_Sph_EC_Off_Corr_Off | C13: 1.5 | D13: 45 | E13: 1.0299883 | F13: 90.14367 | G13: -0.4700117 | H13: 45.14367 | I13: 1 | J13: 0 | K13: =IF(J13=1, "", E13) -> 1.0299883 | L13: =IF(J13=1, "", IF(D13=90, ABS(MOD(F13-D13+180, 360)-180), ABS(IF(ABS(MOD(F13-(180-D13)+180, 360)-180) < ABS(MOD(F13-D13+180, 360)-180), MOD(F13-(180-D13)+180, 360)-180, MOD(F13-D13+180, 360)-180)))) -> 44.85633 | M13: =IF(OR(J13=1, D13=90), 0, IF(ABS(MOD(F13-(180-D13)+180, 360)-180) < ABS(MOD(F13-D13+180, 360)-180), 1, 0)) -> 1
A14: 13 | B14: CircularDVF_Sph_EC_Off_Corr_Off | C14: 0.5 | D14: 0 | E14: 0.98410445 | F14: -179.21806 | G14: 0.48410445 | H14: -179.21806 | I14: 0 | J14: 0 | K14: =IF(J14=1, "", E14) -> 0.98410445 | L14: =IF(J14=1, "", IF(D14=90, ABS(MOD(F14-D14+180, 360)-180), ABS(IF(ABS(MOD(F14-(180-D14)+180, 360)-180) < ABS(MOD(F14-D14+180, 360)-180), MOD(F14-(180-D14)+180, 360)-180, MOD(F14-D14+180, 360)-180)))) -> 0.78194109 | M14: =IF(OR(J14=1, D14=90), 0, IF(ABS(MOD(F14-(180-D14)+180, 360)-180) < ABS(MOD(F14-D14+180, 360)-180), 1, 0)) -> 1
... A151: 150 | B151: CircularDVF_Sph_EC_Off_Corr_Off | C151: 1 | D151: 180 | E151: 1.510889 | F151: -0.11752964 | G151: 0.51088898 | H151: 179.88247 | I151: 1 | J151: 0 | K151: =IF(J151=1, "", E151) -> 1.510889 | L151: =IF(J151=1, "", IF(D151=90, ABS(MOD(F151-D151+180, 360)-180), ABS(IF(ABS(MOD(F151-(180-D151)+180, 360)-180) < ABS(MOD(F151-D151+180, 360)-180), MOD(F151-(180-D151)+180, 360)-180, MOD(F151-D151+180, 360)-180)))) -> 0.11752964 | M151: =IF(OR(J151=1, D151=90), 0, IF(ABS(MOD(F151-(180-D151)+180, 360)-180) < ABS(MOD(F151-D151+180, 360)-180), 1, 0)) -> 1
A152: sub2 1 | B152: CircularDVF_Sph_EC_Off_Corr_Off | C152: 1.5 | D152: 180 | E152: 0.94788244 | F152: 179.56287 | G152: -0.55211756 | H152: -0.43712553 | I152: 0 | J152: 0 | K152: =IF(J152=1, "", E152) -> 0.94788244 | L152: =IF(J152=1, "", IF(D152=90, ABS(MOD(F152-D152+180, 360)-180), ABS(IF(ABS(MOD(F152-(180-D152)+180, 360)-180) < ABS(MOD(F152-D152+180, 360)-180), MOD(F152-(180-D152)+180, 360)-180, MOD(F152-D152+180, 360)-180)))) -> 0.43712553 | M152: =IF(OR(J152=1, D152=90), 0, IF(ABS(MOD(F152-(180-D152)+180, 360)-180) < ABS(MOD(F152-D152+180, 360)-180), 1, 0)) -> 0
A153: 2 | B153: CircularDVF_Sph_EC_Off_Corr_Off | C153: 0.35 | D153: 90 | E153: 1.0196575 | F153: 89.854874 | G153: 0.66965749 | H153: -0.14512578 | I153: 0 | J153: 0 | K153: =IF(J153=1, "", E153) -> 1.0196575 | L153: =IF(J153=1, "", IF(D153=90, ABS(MOD(F153-D153+180, 360)-180), ABS(IF(ABS(MOD(F153-(180-D153)+180, 360)-180) < ABS(MOD(F153-D153+180, 360)-180), MOD(F153-(180-D153)+180, 360)-180, MOD(F153-D153+180, 360)-180)))) -> 0.14512578 | M153: =IF(OR(J153=1, D153=90), 0, IF(ABS(MOD(F153-(180-D153)+180, 360)-180) < ABS(MOD(F153-D153+180, 360)-180), 1, 0)) -> 0
A154: 3 | B154: CircularDVF_Sph_EC_Off_Corr_Off | C154: 0.7 | D154: 45 | E154: 1.0051147 | F154: 58.213099 | G154: 0.30511472 | H154: 13.213099 | I154: 0 | J154: 0 | K154: =IF(J154=1, "", E154) -> 1.0051147 | L154: =IF(J154=1, "", IF(D154=90, ABS(MOD(F154-D154+180, 360)-180), ABS(IF(ABS(MOD(F154-(180-D154)+180, 360)-180) < ABS(MOD(F154-D154+180, 360)-180), MOD(F154-(180-D154)+180, 360)-180, MOD(F154-D154+180, 360)-180)))) -> 13.213099 | M154: =IF(OR(J154=1, D154=90), 0, IF(ABS(MOD(F154-(180-D154)+180, 360)-180) < ABS(MOD(F154-D154+180, 360)-180), 1, 0)) -> 0
A155: 4 | B155: CircularDVF_Sph_EC_Off_Corr_Off | C155: 0.7 | D155: 180 | E155: 1.0668041 | F155: 179.05672 | G155: 0.36680412 | H155: -0.94328353 | I155: 0 | J155: 0 | K155: =IF(J155=1, "", E155) -> 1.0668041 | L155: =IF(J155=1, "", IF(D155=90, ABS(MOD(F155-D155+180, 360)-180), ABS(IF(ABS(MOD(F155-(180-D155)+180, 360)-180) < ABS(MOD(F155-D155+180, 360)-180), MOD(F155-(180-D155)+180, 360)-180, MOD(F155-D155+180, 360)-180)))) -> 0.94328353 | M155: =IF(OR(J155=1, D155=90), 0, IF(ABS(MOD(F155-(180-D155)+180, 360)-180) < ABS(MOD(F155-D155+180, 360)-180), 1, 0)) -> 0
A156: 5 | B156: CircularDVF_Sph_EC_Off_Corr_Off | C156: 0.35 | D156: 45 | E156: 1.0463136 | F156: 129.00879 | G156: 0.69631361 | H156: 84.008791 | I156: 1 | J156: 0 | K156: =IF(J156=1, "", E156) -> 1.0463136 | L156: =IF(J156=1, "", IF(D156=90, ABS(MOD(F156-D156+180, 360)-180), ABS(IF(ABS(MOD(F156-(180-D156)+180, 360)-180) < ABS(MOD(F156-D156+180, 360)-180), MOD(F156-(180-D156)+180, 360)-180, MOD(F156-D156+180, 360)-180)))) -> 5.9912087 | M156: =IF(OR(J156=1, D156=90), 0, IF(ABS(MOD(F156-(180-D156)+180, 360)-180) < ABS(MOD(F156-D156+180, 360)-180), 1, 0)) -> 1
A157: 6 | B157: CircularDVF_Sph_EC_Off_Corr_Off | C157: 0.5 | D157: 45 | E157: 1.0081073 | F157: 115.33082 | G157: 0.50810729 | H157: 70.330816 | I157: 1 | J157: 0 | K157: =IF(J157=1, "", E157) -> 1.0081073 | L157: =IF(J157=1, "", IF(D157=90, ABS(MOD(F157-D157+180, 360)-180), ABS(IF(ABS(MOD(F157-(180-D157)+180, 360)-180) < ABS(MOD(F157-D157+180, 360)-180), MOD(F157-(180-D157)+180, 360)-180, MOD(F157-D157+180, 360)-180)))) -> 19.669184 | M157: =IF(OR(J157=1, D157=90), 0, IF(ABS(MOD(F157-(180-D157)+180, 360)-180) < ABS(MOD(F157-D157+180, 360)-180), 1, 0)) -> 1
A158: 7 | B158: CircularDVF_Sph_EC_Off_Corr_Off | C158: 0.5 | D158: 0 | E158: 1.0043977 | F158: 36.404328 | G158: 0.50439773 | H158: 36.404328 | I158: 0 | J158: 0 | K158: =IF(J158=1, "", E158) -> 1.0043977 | L158: =IF(J158=1, "", IF(D158=90, ABS(MOD(F158-D158+180, 360)-180), ABS(IF(ABS(MOD(F158-(180-D158)+180, 360)-180) < ABS(MOD(F158-D158+180, 360)-180), MOD(F158-(180-D158)+180, 360)-180, MOD(F158-D158+180, 360)-180)))) -> 36.404328 | M158: =IF(OR(J158=1, D158=90), 0, IF(ABS(MOD(F158-(180-D158)+180, 360)-180) < ABS(MOD(F158-D158+180, 360)-180), 1, 0)) -> 0
A159: 8 | B159: CircularDVF_Sph_EC_Off_Corr_Off | C159: 0.5 | D159: 45 | E159: 1.0410959 | F159: 100.14466 | G159: 0.54109594 | H159: 55.144661 | I159: 1 | J159: 0 | K159: =IF(J159=1, "", E159) -> 1.0410959 | L159: =IF(J159=1, "", IF(D159=90, ABS(MOD(F159-D159+180, 360)-180), ABS(IF(ABS(MOD(F159-(180-D159)+180, 360)-180) < ABS(MOD(F159-D159+180, 360)-180), MOD(F159-(180-D159)+180, 360)-180, MOD(F159-D159+180, 360)-180)))) -> 34.855339 | M159: =IF(OR(J159=1, D159=90), 0, IF(ABS(MOD(F159-(180-D159)+180, 360)-180) < ABS(MOD(F159-D159+180, 360)-180), 1, 0)) -> 1
A160: 9 | B160: CircularDVF_Sph_EC_Off_Corr_Off | C160: 0.5 | D160: 90 | E160: 0.96341981 | F160: 88.002834 | G160: 0.46341981 | H160: -1.9971659 | I160: 0 | J160: 0 | K160: =IF(J160=1, "", E160) -> 0.96341981 | L160: =IF(J160=1, "", IF(D160=90, ABS(MOD(F160-D160+180, 360)-180), ABS(IF(ABS(MOD(F160-(180-D160)+180, 360)-180) < ABS(MOD(F160-D160+180, 360)-180), MOD(F160-(180-D160)+180, 360)-180, MOD(F160-D160+180, 360)-180)))) -> 1.9971659 | M160: =IF(OR(J160=1, D160=90), 0, IF(ABS(MOD(F160-(180-D160)+180, 360)-180) < ABS(MOD(F160-D160+180, 360)-180), 1, 0)) -> 0
A161: 10 | B161: CircularDVF_Sph_EC_Off_Corr_Off | C161: 1 | D161: 45 | E161: 1.0025311 | F161: 74.918355 | G161: 0.0025311462 | H161: 29.918355 | I161: 0 | J161: 0 | K161: =IF(J161=1, "", E161) -> 1.0025311 | L161: =IF(J161=1, "", IF(D161=90, ABS(MOD(F161-D161+180, 360)-180), ABS(IF(ABS(MOD(F161-(180-D161)+180, 360)-180) < ABS(MOD(F161-D161+180, 360)-180), MOD(F161-(180-D161)+180, 360)-180, MOD(F161-D161+180, 360)-180)))) -> 29.918355 | M161: =IF(OR(J161=1, D161=90), 0, IF(ABS(MOD(F161-(180-D161)+180, 360)-180) < ABS(MOD(F161-D161+180, 360)-180), 1, 0)) -> 0
A162: 11 | B162: CircularDVF_Sph_EC_Off_Corr_Off | C162: 0.35 | D162: 90 | E162: 1.0093531 | F162: 89.560174 | G162: 0.65935311 | H162: -0.4398259 | I162: 0 | J162: 0 | K162: =IF(J162=1, "", E162) -> 1.0093531 | L162: =IF(J162=1, "", IF(D162=90, ABS(MOD(F162-D162+180, 360)-180), ABS(IF(ABS(MOD(F162-(180-D162)+180, 360)-180) < ABS(MOD(F162-D162+180, 360)-180), MOD(F162-(180-D162)+180, 360)-180, MOD(F162-D162+180, 360)-180)))) -> 0.4398259 | M162: =IF(OR(J162=1, D162=90), 0, IF(ABS(MOD(F162-(180-D162)+180, 360)-180) < ABS(MOD(F162-D162+180, 360)-180), 1, 0)) -> 0
A163: 12 | B163: CircularDVF_Sph_EC_Off_Corr_Off | C163: 0.35 | D163: 180 | E163: 1.1544944 | F163: 179.6411 | G163: 0.80449437 | H163: -0.35889504 | I163: 0 | J163: 0 | K163: =IF(J163=1, "", E163) -> 1.1544944 | L163: =IF(J163=1, "", IF(D163=90, ABS(MOD(F163-D163+180, 360)-180), ABS(IF(ABS(MOD(F163-(180-D163)+180, 360)-180) < ABS(MOD(F163-D163+180, 360)-180), MOD(F163-(180-D163)+180, 360)-180, MOD(F163-D163+180, 360)-180)))) -> 0.35889504 | M163: =IF(OR(J163=1, D163=90), 0, IF(ABS(MOD(F163-(180-D163)+180, 360)-180) < ABS(MOD(F163-D163+180, 360)-180), 1, 0)) -> 0
A164: 13 | B164: CircularDVF_Sph_EC_Off_Corr_Off | C164: 0.35 | D164: 180 | E164: 1.1544944 | F164: 179.6411 | G164: 0.80449437 | H164: -0.35889504 | I164: 0 | J164: 0 | K164: =IF(J164=1, "", E164) -> 1.1544944 | L164: =IF(J164=1, "", IF(D164=90, ABS(MOD(F164-D164+180, 360)-180), ABS(IF(ABS(MOD(F164-(180-D164)+180, 360)-180) < ABS(MOD(F164-D164+180, 360)-180), MOD(F164-(180-D164)+180, 360)-180, MOD(F164-D164+180, 360)-180)))) -> 0.35889504 | M164: =IF(OR(J164=1, D164=90), 0, IF(ABS(MOD(F164-(180-D164)+180, 360)-180) < ABS(MOD(F164-D164+180, 360)-180), 1, 0)) -> 0
... A301: 150 | B301: CircularDVF_Sph_EC_Off_Corr_Off | C301: 1 | D301: 135 | E301: 1.0090729 | F301: 111.78507 | G301: 0.0090728687 | H301: -23.21493 | I301: 0 | J301: 0 | K301: =IF(J301=1, "", E301) -> 1.0090729 | L301: =IF(J301=1, "", IF(D301=90, ABS(MOD(F301-D301+180, 360)-180), ABS(IF(ABS(MOD(F301-(180-D301)+180, 360)-180) < ABS(MOD(F301-D301+180, 360)-180), MOD(F301-(180-D301)+180, 360)-180, MOD(F301-D301+180, 360)-180)))) -> 23.21493 | M301: =IF(OR(J301=1, D301=90), 0, IF(ABS(MOD(F301-(180-D301)+180, 360)-180) < ABS(MOD(F301-D301+180, 360)-180), 1, 0)) -> 0
A302: sub3 1 | B302: CircularDVF_Sph_EC_Off_Corr_Off | C302: 0.35 | D302: 45 | E302: 0.98295421 | F302: 72.412476 | G302: 0.63295421 | H302: 27.412476 | I302: 0 | J302: 0 | K302: =IF(J302=1, "", E302) -> 0.98295421 | L302: =IF(J302=1, "", IF(D302=90, ABS(MOD(F302-D302+180, 360)-180), ABS(IF(ABS(MOD(F302-(180-D302)+180, 360)-180) < ABS(MOD(F302-D302+180, 360)-180), MOD(F302-(180-D302)+180, 360)-180, MOD(F302-D302+180, 360)-180)))) -> 27.412476 | M302: =IF(OR(J302=1, D302=90), 0, IF(ABS(MOD(F302-(180-D302)+180, 360)-180) < ABS(MOD(F302-D302+180, 360)-180), 1, 0)) -> 0
A303: 2 | B303: CircularDVF_Sph_EC_Off_Corr_Off | C303: 1.5 | D303: 180 | E303: 0.4992911 | F303: 144.30384 | G303: -1.0007089 | H303: -35.696162 | I303: 0 | J303: 0 | K303: =IF(J303=1, "", E303) -> 0.4992911 | L303: =IF(J303=1, "", IF(D303=90, ABS(MOD(F303-D303+180, 360)-180), ABS(IF(ABS(MOD(F303-(180-D303)+180, 360)-180) < ABS(MOD(F303-D303+180, 360)-180), MOD(F303-(180-D303)+180, 360)-180, MOD(F303-D303+180, 360)-180)))) -> 35.696162 | M303: =IF(OR(J303=1, D303=90), 0, IF(ABS(MOD(F303-(180-D303)+180, 360)-180) < ABS(MOD(F303-D303+180, 360)-180), 1, 0)) -> 0
A304: 3 | B304: CircularDVF_Sph_EC_Off_Corr_Off | C304: 0.5 | D304: 0 | E304: 1.1069055 | F304: 4.9257321 | G304: 0.60690549 | H304: 4.9257321 | I304: 0 | J304: 0 | K304: =IF(J304=1, "", E304) -> 1.1069055 | L304: =IF(J304=1, "", IF(D304=90, ABS(MOD(F304-D304+180, 360)-180), ABS(IF(ABS(MOD(F304-(180-D304)+180, 360)-180) < ABS(MOD(F304-D304+180, 360)-180), MOD(F304-(180-D304)+180, 360)-180, MOD(F304-D304+180, 360)-180)))) -> 4.9257321 | M304: =IF(OR(J304=1, D304=90), 0, IF(ABS(MOD(F304-(180-D304)+180, 360)-180) < ABS(MOD(F304-D304+180, 360)-180), 1, 0)) -> 0
A305: 4 | B305: CircularDVF_Sph_EC_Off_Corr_Off | C305: 1 | D305: 45 | E305: 1.4794241 | F305: 71.368942 | G305: 0.47942408 | H305: 26.368942 | I305: 0 | J305: 0 | K305: =IF(J305=1, "", E305) -> 1.4794241 | L305: =IF(J305=1, "", IF(D305=90, ABS(MOD(F305-D305+180, 360)-180), ABS(IF(ABS(MOD(F305-(180-D305)+180, 360)-180) < ABS(MOD(F305-D305+180, 360)-180), MOD(F305-(180-D305)+180, 360)-180, MOD(F305-D305+180, 360)-180)))) -> 26.368942 | M305: =IF(OR(J305=1, D305=90), 0, IF(ABS(MOD(F305-(180-D305)+180, 360)-180) < ABS(MOD(F305-D305+180, 360)-180), 1, 0)) -> 0
A306: 5 | B306: CircularDVF_Sph_EC_Off_Corr_Off | C306: 1 | D306: 0 | E306: 0.46715548 | F306: 16.97231 | G306: -0.53284452 | H306: 16.97231 | I306: 0 | J306: 0 | K306: =IF(J306=1, "", E306) -> 0.46715548 | L306: =IF(J306=1, "", IF(D306=90, ABS(MOD(F306-D306+180, 360)-180), ABS(IF(ABS(MOD(F306-(180-D306)+180, 360)-180) < ABS(MOD(F306-D306+180, 360)-180), MOD(F306-(180-D306)+180, 360)-180, MOD(F306-D306+180, 360)-180)))) -> 16.97231 | M306: =IF(OR(J306=1, D306=90), 0, IF(ABS(MOD(F306-(180-D306)+180, 360)-180) < ABS(MOD(F306-D306+180, 360)-180), 1, 0)) -> 0
A307: 6 | B307: CircularDVF_Sph_EC_Off_Corr_Off | C307: 0.5 | D307: 90 | E307: 1.5488808 | F307: 80.110457 | G307: 1.0488808 | H307: -9.8895431 | I307: 0 | J307: 0 | K307: =IF(J307=1, "", E307) -> 1.5488808 | L307: =IF(J307=1, "", IF(D307=90, ABS(MOD(F307-D307+180, 360)-180), ABS(IF(ABS(MOD(F307-(180-D307)+180, 360)-180) < ABS(MOD(F307-D307+180, 360)-180), MOD(F307-(180-D307)+180, 360)-180, MOD(F307-D307+180, 360)-180)))) -> 9.8895431 | M307: =IF(OR(J307=1, D307=90), 0, IF(ABS(MOD(F307-(180-D307)+180, 360)-180) < ABS(MOD(F307-D307+180, 360)-180), 1, 0)) -> 0
A308: 7 | B308: CircularDVF_Sph_EC_Off_Corr_Off | C308: 0.5 | D308: 135 | E308: 0.67362346 | F308: 123.77537 | G308: 0.17362346 | H308: -11.224635 | I308: 0 | J308: 0 | K308: =IF(J308=1, "", E308) -> 0.67362346 | L308: =IF(J308=1, "", IF(D308=90, ABS(MOD(F308-D308+180, 360)-180), ABS(IF(ABS(MOD(F308-(180-D308)+180, 360)-180) < ABS(MOD(F308-D308+180, 360)-180), MOD(F308-(180-D308)+180, 360)-180, MOD(F308-D308+180, 360)-180)))) -> 11.224635 | M308: =IF(OR(J308=1, D308=90), 0, IF(ABS(MOD(F308-(180-D308)+180, 360)-180) < ABS(MOD(F308-D308+180, 360)-180), 1, 0)) -> 0
A309: 8 | B309: CircularDVF_Sph_EC_Off_Corr_Off | C309: 0.5 | D309: 90 | E309: 1.3263552 | F309: 80.699084 | G309: 0.82635524 | H309: -9.3009157 | I309: 0 | J309: 0 | K309: =IF(J309=1, "", E309) -> 1.3263552 | L309: =IF(J309=1, "", IF(D309=90, ABS(MOD(F309-D309+180, 360)-180), ABS(IF(ABS(MOD(F309-(180-D309)+180, 360)-180) < ABS(MOD(F309-D309+180, 360)-180), MOD(F309-(180-D309)+180, 360)-180, MOD(F309-D309+180, 360)-180)))) -> 9.3009157 | M309: =IF(OR(J309=1, D309=90), 0, IF(ABS(MOD(F309-(180-D309)+180, 360)-180) < ABS(MOD(F309-D309+180, 360)-180), 1, 0)) -> 0
A310: 9 | B310: CircularDVF_Sph_EC_Off_Corr_Off | C310: 0.7 | D310: 90 | E310: 1.2671044 | F310: 77.40279 | G310: 0.56710444 | H310: -12.59721 | I310: 0 | J310: 0 | K310: =IF(J310=1, "", E310) -> 1.2671044 | L310: =IF(J310=1, "", IF(D310=90, ABS(MOD(F310-D310+180, 360)-180), ABS(IF(ABS(MOD(F310-(180-D310)+180, 360)-180) < ABS(MOD(F310-D310+180, 360)-180), MOD(F310-(180-D310)+180, 360)-180, MOD(F310-D310+180, 360)-180)))) -> 12.59721 | M310: =IF(OR(J310=1, D310=90), 0, IF(ABS(MOD(F310-(180-D310)+180, 360)-180) < ABS(MOD(F310-D310+180, 360)-180), 1, 0)) -> 0
A311: 10 | B311: CircularDVF_Sph_EC_Off_Corr_Off | C311: 1.5 | D311: 135 | E311: 0.9141134 | F311: 111.72325 | G311: -0.5858866 | H311: -23.276748 | I311: 0 | J311: 0 | K311: =IF(J311=1, "", E311) -> 0.9141134 | L311: =IF(J311=1, "", IF(D311=90, ABS(MOD(F311-D311+180, 360)-180), ABS(IF(ABS(MOD(F311-(180-D311)+180, 360)-180) < ABS(MOD(F311-D311+180, 360)-180), MOD(F311-(180-D311)+180, 360)-180, MOD(F311-D311+180, 360)-180)))) -> 23.276748 | M311: =IF(OR(J311=1, D311=90), 0, IF(ABS(MOD(F311-(180-D311)+180, 360)-180) < ABS(MOD(F311-D311+180, 360)-180), 1, 0)) -> 0
A312: 11 | B312: CircularDVF_Sph_EC_Off_Corr_Off | C312: 1 | D312: 90 | E312: 1.1031702 | F312: 74.10251 | G312: 0.10317019 | H312: -15.89749 | I312: 0 | J312: 0 | K312: =IF(J312=1, "", E312) -> 1.1031702 | L312: =IF(J312=1, "", IF(D312=90, ABS(MOD(F312-D312+180, 360)-180), ABS(IF(ABS(MOD(F312-(180-D312)+180, 360)-180) < ABS(MOD(F312-D312+180, 360)-180), MOD(F312-(180-D312)+180, 360)-180, MOD(F312-D312+180, 360)-180)))) -> 15.89749 | M312: =IF(OR(J312=1, D312=90), 0, IF(ABS(MOD(F312-(180-D312)+180, 360)-180) < ABS(MOD(F312-D312+180, 360)-180), 1, 0)) -> 0
...

Sheet A_avarage
A1: 行ラベル | B1: 平均 / 分析距離 | C1: 標準偏差 / 分析距離2 | D1: 数値の個数 / 分析距離3 | E1: 平均 / 有効角度誤差 | F1: 標準偏差 / 有効角度誤差2 | G1: 数値の個数 / 有効角度誤差3
A2: 0 | B2: 0.68130176 | C2: 0.28957619 | D2: 363 | E2: 7.7897615 | F2: 14.997573 | G2: 363
A3: 0.35 | B3: 0.75128282 | C3: 0.27461359 | D3: 73 | E3: 8.4363374 | F3: 16.530056 | G3: 73
A4: 0.5 | B4: 0.73990975 | C4: 0.28518684 | D4: 70 | E4: 6.4077887 | F4: 11.615941 | G4: 70
A5: 0.7 | B5: 0.63309043 | C5: 0.28078666 | D5: 74 | E5: 8.2962457 | F5: 14.557592 | G5: 74
A6: 1 | B6: 0.66232135 | C6: 0.29959638 | D6: 73 | E6: 8.2563545 | F6: 17.948354 | G6: 73
A7: 1.5 | B7: 0.6229734 | C7: 0.28210608 | D7: 73 | E7: 7.4883499 | F7: 13.268677 | G7: 73
A8: 45 | B8: 0.91962852 | C8: 0.35558863 | D8: 390 | E8: 18.966892 | F8: 16.193551 | G8: 390
A9: 0.35 | B9: 0.90510778 | C9: 0.34676054 | D9: 78 | E9: 18.433541 | F9: 15.709978 | G9: 78
A10: 0.5 | B10: 0.91428677 | C10: 0.3548458 | D10: 78 | E10: 20.540601 | F10: 17.205585 | G10: 78
A11: 0.7 | B11: 0.9172527 | C11: 0.33585066 | D11: 78 | E11: 17.555957 | F11: 16.089001 | G11: 78
A12: 1 | B12: 0.92646772 | C12: 0.39321221 | D12: 78 | E12: 18.450953 | F12: 15.194603 | G12: 78
A13: 1.5 | B13: 0.93502761 | C13: 0.34368228 | D13: 78 | E13: 19.85341 | F13: 16.51618 | G13: 78
... A31: 1.5 | B31: 0.99518569 | C31: 0.39525419 | D31: 73 | E31: 6.3544409 | F31: 15.715975 | G31: 73
A32: 総計 | B32: 0.91875456 | C32: 0.36685047 | D32: 1900 | E32: 10.136509 | F32: 14.508644 | G32: 1900

Sheet B
B1: Condition | C1: TargetDist | D1: TargetAngle | E1: RespDist | F1: RespAngle | G1: ErrDist | H1: ErrAngle | I1: FBConf | J1: IsInsideHead | K1: 分析距離 | L1: 有効角度誤差 | M1: New FB
B2: CircularDVF_Sph_EC_On_Corr_Off | C2: 1.5 | D2: 180 | E2: 1.0267425 | F2: 2.9991525 | G2: -0.4732575 | H2: -177.00085 | I2: 1 | J2: 0 | K2: =IF(J2=1, "", E2) -> 1.0267425 | L2: =IF(J2=1, "", IF(D2=90, ABS(MOD(F2-D2+180, 360)-180), ABS(IF(ABS(MOD(F2-(180-D2)+180, 360)-180) < ABS(MOD(F2-D2+180, 360)-180), MOD(F2-(180-D2)+180, 360)-180, MOD(F2-D2+180, 360)-180)))) -> 2.9991525 | M2: =IF(OR(J2=1, D2=90), 0, IF(ABS(MOD(F2-(180-D2)+180, 360)-180) < ABS(MOD(F2-D2+180, 360)-180), 1, 0)) -> 1
B3: CircularDVF_Sph_EC_On_Corr_Off | C3: 0.5 | D3: 0 | E3: 0.95826589 | F3: 0.74125175 | G3: 0.45826589 | H3: 0.74125175 | I3: 0 | J3: 0 | K3: =IF(J3=1, "", E3) -> 0.95826589 | L3: =IF(J3=1, "", IF(D3=90, ABS(MOD(F3-D3+180, 360)-180), ABS(IF(ABS(MOD(F3-(180-D3)+180, 360)-180) < ABS(MOD(F3-D3+180, 360)-180), MOD(F3-(180-D3)+180, 360)-180, MOD(F3-D3+180, 360)-180)))) -> 0.74125175 | M3: =IF(OR(J3=1, D3=90), 0, IF(ABS(MOD(F3-(180-D3)+180, 360)-180) < ABS(MOD(F3-D3+180, 360)-180), 1, 0)) -> 0
B4: CircularDVF_Sph_EC_On_Corr_Off | C4: 1 | D4: 0 | E4: 0.54196596 | F4: 5.1400451 | G4: -0.45803404 | H4: 5.1400451 | I4: 0 | J4: 0 | K4: =IF(J4=1, "", E4) -> 0.54196596 | L4: =IF(J4=1, "", IF(D4=90, ABS(MOD(F4-D4+180, 360)-180), ABS(IF(ABS(MOD(F4-(180-D4)+180, 360)-180) < ABS(MOD(F4-D4+180, 360)-180), MOD(F4-(180-D4)+180, 360)-180, MOD(F4-D4+180, 360)-180)))) -> 5.1400451 | M4: =IF(OR(J4=1, D4=90), 0, IF(ABS(MOD(F4-(180-D4)+180, 360)-180) < ABS(MOD(F4-D4+180, 360)-180), 1, 0)) -> 0
B5: CircularDVF_Sph_EC_On_Corr_Off | C5: 0.7 | D5: 0 | E5: 0.54196596 | F5: 5.1400451 | G5: -0.15803404 | H5: 5.1400451 | I5: 0 | J5: 0 | K5: =IF(J5=1, "", E5) -> 0.54196596 | L5: =IF(J5=1, "", IF(D5=90, ABS(MOD(F5-D5+180, 360)-180), ABS(IF(ABS(MOD(F5-(180-D5)+180, 360)-180) < ABS(MOD(F5-D5+180, 360)-180), MOD(F5-(180-D5)+180, 360)-180, MOD(F5-D5+180, 360)-180)))) -> 5.1400451 | M5: =IF(OR(J5=1, D5=90), 0, IF(ABS(MOD(F5-(180-D5)+180, 360)-180) < ABS(MOD(F5-D5+180, 360)-180), 1, 0)) -> 0
B6: CircularDVF_Sph_EC_On_Corr_Off | C6: 1 | D6: 90 | E6: 0.9749986 | F6: 58.187672 | G6: -0.025001401 | H6: -31.812328 | I6: 0 | J6: 0 | K6: =IF(J6=1, "", E6) -> 0.9749986 | L6: =IF(J6=1, "", IF(D6=90, ABS(MOD(F6-D6+180, 360)-180), ABS(IF(ABS(MOD(F6-(180-D6)+180, 360)-180) < ABS(MOD(F6-D6+180, 360)-180), MOD(F6-(180-D6)+180, 360)-180, MOD(F6-D6+180, 360)-180)))) -> 31.812328 | M6: =IF(OR(J6=1, D6=90), 0, IF(ABS(MOD(F6-(180-D6)+180, 360)-180) < ABS(MOD(F6-D6+180, 360)-180), 1, 0)) -> 0
B7: CircularDVF_Sph_EC_On_Corr_Off | C7: 0.35 | D7: 0 | E7: 0.88073406 | F7: 179.52955 | G7: 0.53073406 | H7: 179.52955 | I7: 1 | J7: 0 | K7: =IF(J7=1, "", E7) -> 0.88073406 | L7: =IF(J7=1, "", IF(D7=90, ABS(MOD(F7-D7+180, 360)-180), ABS(IF(ABS(MOD(F7-(180-D7)+180, 360)-180) < ABS(MOD(F7-D7+180, 360)-180), MOD(F7-(180-D7)+180, 360)-180, MOD(F7-D7+180, 360)-180)))) -> 0.47045331 | M7: =IF(OR(J7=1, D7=90), 0, IF(ABS(MOD(F7-(180-D7)+180, 360)-180) < ABS(MOD(F7-D7+180, 360)-180), 1, 0)) -> 1
B8: CircularDVF_Sph_EC_On_Corr_Off | C8: 0.5 | D8: 90 | E8: 0.69446802 | F8: 88.50826 | G8: 0.19446802 | H8: -1.4917404 | I8: 0 | J8: 0 | K8: =IF(J8=1, "", E8) -> 0.69446802 | L8: =IF(J8=1, "", IF(D8=90, ABS(MOD(F8-D8+180, 360)-180), ABS(IF(ABS(MOD(F8-(180-D8)+180, 360)-180) < ABS(MOD(F8-D8+180, 360)-180), MOD(F8-(180-D8)+180, 360)-180, MOD(F8-D8+180, 360)-180)))) -> 1.4917404 | M8: =IF(OR(J8=1, D8=90), 0, IF(ABS(MOD(F8-(180-D8)+180, 360)-180) < ABS(MOD(F8-D8+180, 360)-180), 1, 0)) -> 0
B9: CircularDVF_Sph_EC_On_Corr_Off | C9: 0.35 | D9: 0 | E9: 0.87564195 | F9: -179.1212 | G9: 0.52564195 | H9: -179.1212 | I9: 0 | J9: 0 | K9: =IF(J9=1, "", E9) -> 0.87564195 | L9: =IF(J9=1, "", IF(D9=90, ABS(MOD(F9-D9+180, 360)-180), ABS(IF(ABS(MOD(F9-(180-D9)+180, 360)-180) < ABS(MOD(F9-D9+180, 360)-180), MOD(F9-(180-D9)+180, 360)-180, MOD(F9-D9+180, 360)-180)))) -> 0.87880439 | M9: =IF(OR(J9=1, D9=90), 0, IF(ABS(MOD(F9-(180-D9)+180, 360)-180) < ABS(MOD(F9-D9+180, 360)-180), 1, 0)) -> 1
B10: CircularDVF_Sph_EC_On_Corr_Off | C10: 0.35 | D10: 180 | E10: 1.474903 | F10: 179.11705 | G10: 1.124903 | H10: -0.88294737 | I10: 0 | J10: 0 | K10: =IF(J10=1, "", E10) -> 1.474903 | L10: =IF(J10=1, "", IF(D10=90, ABS(MOD(F10-D10+180, 360)-180), ABS(IF(ABS(MOD(F10-(180-D10)+180, 360)-180) < ABS(MOD(F10-D10+180, 360)-180), MOD(F10-(180-D10)+180, 360)-180, MOD(F10-D10+180, 360)-180)))) -> 0.88294737 | M10: =IF(OR(J10=1, D10=90), 0, IF(ABS(MOD(F10-(180-D10)+180, 360)-180) < ABS(MOD(F10-D10+180, 360)-180), 1, 0)) -> 0
B11: CircularDVF_Sph_EC_On_Corr_Off | C11: 1.5 | D11: 135 | E11: 1.0094588 | F11: 127.32727 | G11: -0.49054116 | H11: -7.672731 | I11: 0 | J11: 0 | K11: =IF(J11=1, "", E11) -> 1.0094588 | L11: =IF(J11=1, "", IF(D11=90, ABS(MOD(F11-D11+180, 360)-180), ABS(IF(ABS(MOD(F11-(180-D11)+180, 360)-180) < ABS(MOD(F11-D11+180, 360)-180), MOD(F11-(180-D11)+180, 360)-180, MOD(F11-D11+180, 360)-180)))) -> 7.672731 | M11: =IF(OR(J11=1, D11=90), 0, IF(ABS(MOD(F11-(180-D11)+180, 360)-180) < ABS(MOD(F11-D11+180, 360)-180), 1, 0)) -> 0
B12: CircularDVF_Sph_EC_On_Corr_Off | C12: 1 | D12: 135 | E12: 1.0094588 | F12: 127.32727 | G12: 0.0094588433 | H12: -7.672731 | I12: 0 | J12: 0 | K12: =IF(J12=1, "", E12) -> 1.0094588 | L12: =IF(J12=1, "", IF(D12=90, ABS(MOD(F12-D12+180, 360)-180), ABS(IF(ABS(MOD(F12-(180-D12)+180, 360)-180) < ABS(MOD(F12-D12+180, 360)-180), MOD(F12-(180-D12)+180, 360)-180, MOD(F12-D12+180, 360)-180)))) -> 7.672731 | M12: =IF(OR(J12=1, D12=90), 0, IF(ABS(MOD(F12-(180-D12)+180, 360)-180) < ABS(MOD(F12-D12+180, 360)-180), 1, 0)) -> 0
B13: CircularDVF_Sph_EC_On_Corr_Off | C13: 0.35 | D13: 0 | E13: 1.0099292 | F13: -0.76194499 | G13: 0.65992922 | H13: -0.76194499 | I13: 0 | J13: 0 | K13: =IF(J13=1, "", E13) -> 1.0099292 | L13: =IF(J13=1, "", IF(D13=90, ABS(MOD(F13-D13+180, 360)-180), ABS(IF(ABS(MOD(F13-(180-D13)+180, 360)-180) < ABS(MOD(F13-D13+180, 360)-180), MOD(F13-(180-D13)+180, 360)-180, MOD(F13-D13+180, 360)-180)))) -> 0.76194499 | M13: =IF(OR(J13=1, D13=90), 0, IF(ABS(MOD(F13-(180-D13)+180, 360)-180) < ABS(MOD(F13-D13+180, 360)-180), 1, 0)) -> 0
... B1951: CircularDVF_Sph_EC_On_Corr_Off | C1951: 1 | D1951: 135 | E1951: 1.4343029 | F1951: 131.36451 | G1951: 0.43430289 | H1951: -3.6354932 | I1951: 0 | J1951: 0 | K1951: =IF(J1951=1, "", E1951) -> 1.4343029 | L1951: =IF(J1951=1, "", IF(D1951=90, ABS(MOD(F1951-D1951+180, 360)-180), ABS(IF(ABS(MOD(F1951-(180-D1951)+180, 360)-180) < ABS(MOD(F1951-D1951+180, 360)-180), MOD(F1951-(180-D1951)+180, 360)-180, MOD(F1951-D1951+180, 360)-180)))) -> 3.6354932 | M1951: =IF(OR(J1951=1, D1951=90), 0, IF(ABS(MOD(F1951-(180-D1951)+180, 360)-180) < ABS(MOD(F1951-D1951+180, 360)-180), 1, 0)) -> 0

Sheet B_avarage
A1: 行ラベル | B1: 平均 / 分析距離 | C1: 標準偏差 / 分析距離2 | D1: 数値の個数 / 分析距離3 | E1: 平均 / 有効角度誤差 | F1: 標準偏差 / 有効角度誤差2 | G1: 数値の個数 / 有効角度誤差3
A2: 0 | B2: 0.66477669 | C2: 0.28095847 | D2: 384 | E2: 8.0106878 | F2: 13.916177 | G2: 384
A3: 0.35 | B3: 0.71382548 | C3: 0.27675943 | D3: 77 | E3: 9.537767 | F3: 17.072045 | G3: 77
A4: 0.5 | B4: 0.70110135 | C4: 0.28644665 | D4: 78 | E4: 7.6660181 | F4: 13.016915 | G4: 78
A5: 0.7 | B5: 0.6092886 | C5: 0.24442628 | D5: 76 | E5: 7.2129893 | F5: 12.667947 | G5: 76
A6: 1 | B6: 0.6795806 | C6: 0.29129199 | D6: 77 | E6: 8.3472452 | F6: 13.134229 | G6: 77
A7: 1.5 | B7: 0.61829136 | C7: 0.28646671 | D7: 76 | E7: 7.273968 | F7: 13.048781 | G7: 76
A8: 45 | B8: 0.9070644 | C8: 0.31617322 | D8: 390 | E8: 18.652787 | F8: 15.901909 | G8: 390
A9: 0.35 | B9: 0.8918035 | C9: 0.36404854 | D9: 78 | E9: 18.92995 | F9: 16.197219 | G9: 78
A10: 0.5 | B10: 0.94531801 | C10: 0.33492832 | D10: 78 | E10: 21.173683 | F10: 16.148864 | G10: 78
A11: 0.7 | B11: 0.88646453 | C11: 0.26568966 | D11: 78 | E11: 14.059906 | F11: 14.443512 | G11: 78
A12: 1 | B12: 0.90131647 | C12: 0.30397859 | D12: 78 | E12: 20.619511 | F12: 16.044179 | G12: 78
A13: 1.5 | B13: 0.91041951 | C13: 0.29993392 | D13: 78 | E13: 18.480883 | F13: 15.612921 | G13: 78
... A31: 1.5 | B31: 0.99931617 | C31: 0.40289327 | D31: 77 | E31: 5.5011004 | F31: 13.153727 | G31: 77
A32: 総計 | B32: 0.90750275 | C32: 0.34921884 | D32: 1941 | E32: 10.024404 | F32: 13.7295 | G32: 1941

Sheet C
B1: Condition | C1: TargetDist | D1: TargetAngle | E1: RespDist | F1: RespAngle | G1: ErrDist | H1: ErrAngle | I1: FBConf | J1: IsInsideHead | K1: 分析距離 | L1: 有効角度誤差 | M1: New FB
B2: CircularDVF_Sph_EC_On_Corr_On | C2: 0.35 | D2: 45 | E2: 0.93729574 | F2: 91.421048 | G2: 0.58729574 | H2: 46.421048 | I2: 1 | J2: 0 | K2: =IF(J2=1, "", E2) -> 0.93729574 | L2: =IF(J2=1, "", IF(D2=90, ABS(MOD(F2-D2+180, 360)-180), ABS(IF(ABS(MOD(F2-(180-D2)+180, 360)-180) < ABS(MOD(F2-D2+180, 360)-180), MOD(F2-(180-D2)+180, 360)-180, MOD(F2-D2+180, 360)-180)))) -> 43.578952 | M2: =IF(OR(J2=1, D2=90), 0, IF(ABS(MOD(F2-(180-D2)+180, 360)-180) < ABS(MOD(F2-D2+180, 360)-180), 1, 0)) -> 1
B3: CircularDVF_Sph_EC_On_Corr_On | C3: 1.5 | D3: 180 | E3: 0.99460336 | F3: 1.3093898 | G3: -0.50539664 | H3: -178.69061 | I3: 1 | J3: 0 | K3: =IF(J3=1, "", E3) -> 0.99460336 | L3: =IF(J3=1, "", IF(D3=90, ABS(MOD(F3-D3+180, 360)-180), ABS(IF(ABS(MOD(F3-(180-D3)+180, 360)-180) < ABS(MOD(F3-D3+180, 360)-180), MOD(F3-(180-D3)+180, 360)-180, MOD(F3-D3+180, 360)-180)))) -> 1.3093898 | M3: =IF(OR(J3=1, D3=90), 0, IF(ABS(MOD(F3-(180-D3)+180, 360)-180) < ABS(MOD(F3-D3+180, 360)-180), 1, 0)) -> 1
B4: CircularDVF_Sph_EC_On_Corr_On | C4: 0.5 | D4: 0 | E4: 0.99460336 | F4: 1.3093898 | G4: 0.49460336 | H4: 1.3093898 | I4: 0 | J4: 0 | K4: =IF(J4=1, "", E4) -> 0.99460336 | L4: =IF(J4=1, "", IF(D4=90, ABS(MOD(F4-D4+180, 360)-180), ABS(IF(ABS(MOD(F4-(180-D4)+180, 360)-180) < ABS(MOD(F4-D4+180, 360)-180), MOD(F4-(180-D4)+180, 360)-180, MOD(F4-D4+180, 360)-180)))) -> 1.3093898 | M4: =IF(OR(J4=1, D4=90), 0, IF(ABS(MOD(F4-(180-D4)+180, 360)-180) < ABS(MOD(F4-D4+180, 360)-180), 1, 0)) -> 0
B5: CircularDVF_Sph_EC_On_Corr_On | C5: 1 | D5: 45 | E5: 0.98352678 | F5: 90.451375 | G5: -0.016473215 | H5: 45.451375 | I5: 1 | J5: 0 | K5: =IF(J5=1, "", E5) -> 0.98352678 | L5: =IF(J5=1, "", IF(D5=90, ABS(MOD(F5-D5+180, 360)-180), ABS(IF(ABS(MOD(F5-(180-D5)+180, 360)-180) < ABS(MOD(F5-D5+180, 360)-180), MOD(F5-(180-D5)+180, 360)-180, MOD(F5-D5+180, 360)-180)))) -> 44.548625 | M5: =IF(OR(J5=1, D5=90), 0, IF(ABS(MOD(F5-(180-D5)+180, 360)-180) < ABS(MOD(F5-D5+180, 360)-180), 1, 0)) -> 1
B6: CircularDVF_Sph_EC_On_Corr_On | C6: 1 | D6: 0 | E6: 1.0460713 | F6: 0.6790293 | G6: 0.046071327 | H6: 0.6790293 | I6: 0 | J6: 0 | K6: =IF(J6=1, "", E6) -> 1.0460713 | L6: =IF(J6=1, "", IF(D6=90, ABS(MOD(F6-D6+180, 360)-180), ABS(IF(ABS(MOD(F6-(180-D6)+180, 360)-180) < ABS(MOD(F6-D6+180, 360)-180), MOD(F6-(180-D6)+180, 360)-180, MOD(F6-D6+180, 360)-180)))) -> 0.6790293 | M6: =IF(OR(J6=1, D6=90), 0, IF(ABS(MOD(F6-(180-D6)+180, 360)-180) < ABS(MOD(F6-D6+180, 360)-180), 1, 0)) -> 0
B7: CircularDVF_Sph_EC_On_Corr_On | C7: 0.5 | D7: 90 | E7: 1.0044296 | F7: 52.081084 | G7: 0.5044296 | H7: -37.918916 | I7: 0 | J7: 0 | K7: =IF(J7=1, "", E7) -> 1.0044296 | L7: =IF(J7=1, "", IF(D7=90, ABS(MOD(F7-D7+180, 360)-180), ABS(IF(ABS(MOD(F7-(180-D7)+180, 360)-180) < ABS(MOD(F7-D7+180, 360)-180), MOD(F7-(180-D7)+180, 360)-180, MOD(F7-D7+180, 360)-180)))) -> 37.918916 | M7: =IF(OR(J7=1, D7=90), 0, IF(ABS(MOD(F7-(180-D7)+180, 360)-180) < ABS(MOD(F7-D7+180, 360)-180), 1, 0)) -> 0
B8: CircularDVF_Sph_EC_On_Corr_On | C8: 0.5 | D8: 135 | E8: 0.99871005 | F8: 128.93286 | G8: 0.49871005 | H8: -6.0671364 | I8: 0 | J8: 0 | K8: =IF(J8=1, "", E8) -> 0.99871005 | L8: =IF(J8=1, "", IF(D8=90, ABS(MOD(F8-D8+180, 360)-180), ABS(IF(ABS(MOD(F8-(180-D8)+180, 360)-180) < ABS(MOD(F8-D8+180, 360)-180), MOD(F8-(180-D8)+180, 360)-180, MOD(F8-D8+180, 360)-180)))) -> 6.0671364 | M8: =IF(OR(J8=1, D8=90), 0, IF(ABS(MOD(F8-(180-D8)+180, 360)-180) < ABS(MOD(F8-D8+180, 360)-180), 1, 0)) -> 0
B9: CircularDVF_Sph_EC_On_Corr_On | C9: 0.5 | D9: 90 | E9: 0.98882697 | F9: 88.952388 | G9: 0.48882697 | H9: -1.0476117 | I9: 0 | J9: 0 | K9: =IF(J9=1, "", E9) -> 0.98882697 | L9: =IF(J9=1, "", IF(D9=90, ABS(MOD(F9-D9+180, 360)-180), ABS(IF(ABS(MOD(F9-(180-D9)+180, 360)-180) < ABS(MOD(F9-D9+180, 360)-180), MOD(F9-(180-D9)+180, 360)-180, MOD(F9-D9+180, 360)-180)))) -> 1.0476117 | M9: =IF(OR(J9=1, D9=90), 0, IF(ABS(MOD(F9-(180-D9)+180, 360)-180) < ABS(MOD(F9-D9+180, 360)-180), 1, 0)) -> 0
B10: CircularDVF_Sph_EC_On_Corr_On | C10: 0.7 | D10: 90 | E10: 0.98882697 | F10: 88.952388 | G10: 0.28882697 | H10: -1.0476117 | I10: 0 | J10: 0 | K10: =IF(J10=1, "", E10) -> 0.98882697 | L10: =IF(J10=1, "", IF(D10=90, ABS(MOD(F10-D10+180, 360)-180), ABS(IF(ABS(MOD(F10-(180-D10)+180, 360)-180) < ABS(MOD(F10-D10+180, 360)-180), MOD(F10-(180-D10)+180, 360)-180, MOD(F10-D10+180, 360)-180)))) -> 1.0476117 | M10: =IF(OR(J10=1, D10=90), 0, IF(ABS(MOD(F10-(180-D10)+180, 360)-180) < ABS(MOD(F10-D10+180, 360)-180), 1, 0)) -> 0
B11: CircularDVF_Sph_EC_On_Corr_On | C11: 1.5 | D11: 135 | E11: 1.5014114 | F11: 127.88709 | G11: 0.0014114136 | H11: -7.1129144 | I11: 0 | J11: 0 | K11: =IF(J11=1, "", E11) -> 1.5014114 | L11: =IF(J11=1, "", IF(D11=90, ABS(MOD(F11-D11+180, 360)-180), ABS(IF(ABS(MOD(F11-(180-D11)+180, 360)-180) < ABS(MOD(F11-D11+180, 360)-180), MOD(F11-(180-D11)+180, 360)-180, MOD(F11-D11+180, 360)-180)))) -> 7.1129144 | M11: =IF(OR(J11=1, D11=90), 0, IF(ABS(MOD(F11-(180-D11)+180, 360)-180) < ABS(MOD(F11-D11+180, 360)-180), 1, 0)) -> 0
B12: CircularDVF_Sph_EC_On_Corr_On | C12: 1 | D12: 90 | E12: 0.98874602 | F12: 89.251665 | G12: -0.011253981 | H12: -0.74833492 | I12: 0 | J12: 0 | K12: =IF(J12=1, "", E12) -> 0.98874602 | L12: =IF(J12=1, "", IF(D12=90, ABS(MOD(F12-D12+180, 360)-180), ABS(IF(ABS(MOD(F12-(180-D12)+180, 360)-180) < ABS(MOD(F12-D12+180, 360)-180), MOD(F12-(180-D12)+180, 360)-180, MOD(F12-D12+180, 360)-180)))) -> 0.74833492 | M12: =IF(OR(J12=1, D12=90), 0, IF(ABS(MOD(F12-(180-D12)+180, 360)-180) < ABS(MOD(F12-D12+180, 360)-180), 1, 0)) -> 0
B13: CircularDVF_Sph_EC_On_Corr_On | C13: 1.5 | D13: 0 | E13: 1.0155436 | F13: 1.8654626 | G13: -0.48445645 | H13: 1.8654626 | I13: 0 | J13: 0 | K13: =IF(J13=1, "", E13) -> 1.0155436 | L13: =IF(J13=1, "", IF(D13=90, ABS(MOD(F13-D13+180, 360)-180), ABS(IF(ABS(MOD(F13-(180-D13)+180, 360)-180) < ABS(MOD(F13-D13+180, 360)-180), MOD(F13-(180-D13)+180, 360)-180, MOD(F13-D13+180, 360)-180)))) -> 1.8654626 | M13: =IF(OR(J13=1, D13=90), 0, IF(ABS(MOD(F13-(180-D13)+180, 360)-180) < ABS(MOD(F13-D13+180, 360)-180), 1, 0)) -> 0
... B1951: CircularDVF_Sph_EC_On_Corr_On | C1951: 1 | D1951: 180 | E1951: 0.8758339 | F1951: 178.51301 | G1951: -0.1241661 | H1951: -1.4869901 | I1951: 0 | J1951: 0 | K1951: =IF(J1951=1, "", E1951) -> 0.8758339 | L1951: =IF(J1951=1, "", IF(D1951=90, ABS(MOD(F1951-D1951+180, 360)-180), ABS(IF(ABS(MOD(F1951-(180-D1951)+180, 360)-180) < ABS(MOD(F1951-D1951+180, 360)-180), MOD(F1951-(180-D1951)+180, 360)-180, MOD(F1951-D1951+180, 360)-180)))) -> 1.4869901 | M1951: =IF(OR(J1951=1, D1951=90), 0, IF(ABS(MOD(F1951-(180-D1951)+180, 360)-180) < ABS(MOD(F1951-D1951+180, 360)-180), 1, 0)) -> 0

Sheet C_avarage 
A1: 行ラベル | B1: 平均 / 分析距離 | C1: 標準偏差 / 分析距離2 | D1: 数値の個数 / 分析距離3 | E1: 平均 / 有効角度誤差 | F1: 標準偏差 / 有効角度誤差2 | G1: 数値の個数 / 有効角度誤差3
A2: 0 | B2: 0.73418963 | C2: 0.35128653 | D2: 352 | E2: 8.1624691 | F2: 15.086098 | G2: 352
A3: 0.35 | B3: 0.91445996 | C3: 0.4549026 | D3: 69 | E3: 6.8936657 | F3: 12.943215 | G3: 69
A4: 0.5 | B4: 0.74789657 | C4: 0.33140708 | D4: 71 | E4: 7.0422583 | F4: 13.018093 | G4: 71
A5: 0.7 | B5: 0.72582261 | C5: 0.32020133 | D5: 74 | E5: 10.012254 | F5: 17.556389 | G5: 74
A6: 1 | B6: 0.63729715 | C6: 0.28602418 | D6: 69 | E6: 8.4248115 | F6: 15.029188 | G6: 69
A7: 1.5 | B7: 0.64568089 | C7: 0.26042961 | D7: 69 | E7: 8.3377833 | F7: 16.000685 | G7: 69
A8: 45 | B8: 0.85558531 | C8: 0.30592391 | D8: 390 | E8: 18.46621 | F8: 15.933807 | G8: 390
A9: 0.35 | B9: 0.88252891 | C9: 0.25954656 | D9: 78 | E9: 19.756872 | F9: 16.366485 | G9: 78
A10: 0.5 | B10: 0.87967239 | C10: 0.30764139 | D10: 78 | E10: 14.954728 | F10: 14.507366 | G10: 78
A11: 0.7 | B11: 0.83166216 | C11: 0.325361 | D11: 78 | E11: 19.77568 | F11: 16.30372 | G11: 78
A12: 1 | B12: 0.86241715 | C12: 0.33471373 | D12: 78 | E12: 20.681711 | F12: 16.724975 | G12: 78
A13: 1.5 | B13: 0.82164594 | C13: 0.29149523 | D13: 78 | E13: 17.162057 | F13: 14.941526 | G13: 78
... A31: 1.5 | B31: 1.0423843 | C31: 0.41574443 | D31: 72 | E31: 5.1977147 | F31: 12.626132 | G31: 72
A32: 総計 | B32: 0.90880313 | C32: 0.3672361 | D32: 1883 | E32: 10.050986 | F32: 14.408744 | G32: 1883

Sheet D
B1: Condition | C1: TargetDist | D1: TargetAngle | E1: RespDist | F1: RespAngle | G1: ErrDist | H1: ErrAngle | I1: FBConf | J1: IsInsideHead | K1: 分析距離 | L1: 有効角度誤差 | M1: New FB
B2: CircularDVF_Rigid_EC_Off_Corr_Off | C2: 0.7 | D2: 45 | E2: 0.49284213 | F2: 89.099197 | G2: -0.20715787 | H2: 44.099197 | I2: 0 | J2: 0 | K2: =IF(J2=1, "", E2) -> 0.49284213 | L2: =IF(J2=1, "", IF(D2=90, ABS(MOD(F2-D2+180, 360)-180), ABS(IF(ABS(MOD(F2-(180-D2)+180, 360)-180) < ABS(MOD(F2-D2+180, 360)-180), MOD(F2-(180-D2)+180, 360)-180, MOD(F2-D2+180, 360)-180)))) -> 44.099197 | M2: =IF(OR(J2=1, D2=90), 0, IF(ABS(MOD(F2-(180-D2)+180, 360)-180) < ABS(MOD(F2-D2+180, 360)-180), 1, 0)) -> 0
B3: CircularDVF_Rigid_EC_Off_Corr_Off | C3: 1.5 | D3: 45 | E3: 0.81823946 | F3: 90.542557 | G3: -0.68176054 | H3: 45.542557 | I3: 1 | J3: 0 | K3: =IF(J3=1, "", E3) -> 0.81823946 | L3: =IF(J3=1, "", IF(D3=90, ABS(MOD(F3-D3+180, 360)-180), ABS(IF(ABS(MOD(F3-(180-D3)+180, 360)-180) < ABS(MOD(F3-D3+180, 360)-180), MOD(F3-(180-D3)+180, 360)-180, MOD(F3-D3+180, 360)-180)))) -> 44.457443 | M3: =IF(OR(J3=1, D3=90), 0, IF(ABS(MOD(F3-(180-D3)+180, 360)-180) < ABS(MOD(F3-D3+180, 360)-180), 1, 0)) -> 1
B4: CircularDVF_Rigid_EC_Off_Corr_Off | C4: 0.5 | D4: 0 | E4: 1.0099926 | F4: 0.9963479 | G4: 0.50999262 | H4: 0.9963479 | I4: 0 | J4: 0 | K4: =IF(J4=1, "", E4) -> 1.0099926 | L4: =IF(J4=1, "", IF(D4=90, ABS(MOD(F4-D4+180, 360)-180), ABS(IF(ABS(MOD(F4-(180-D4)+180, 360)-180) < ABS(MOD(F4-D4+180, 360)-180), MOD(F4-(180-D4)+180, 360)-180, MOD(F4-D4+180, 360)-180)))) -> 0.9963479 | M4: =IF(OR(J4=1, D4=90), 0, IF(ABS(MOD(F4-(180-D4)+180, 360)-180) < ABS(MOD(F4-D4+180, 360)-180), 1, 0)) -> 0
B5: CircularDVF_Rigid_EC_Off_Corr_Off | C5: 1 | D5: 135 | E5: 0.99718607 | F5: 133.34185 | G5: -0.00281393 | H5: -1.6581542 | I5: 0 | J5: 0 | K5: =IF(J5=1, "", E5) -> 0.99718607 | L5: =IF(J5=1, "", IF(D5=90, ABS(MOD(F5-D5+180, 360)-180), ABS(IF(ABS(MOD(F5-(180-D5)+180, 360)-180) < ABS(MOD(F5-D5+180, 360)-180), MOD(F5-(180-D5)+180, 360)-180, MOD(F5-D5+180, 360)-180)))) -> 1.6581542 | M5: =IF(OR(J5=1, D5=90), 0, IF(ABS(MOD(F5-(180-D5)+180, 360)-180) < ABS(MOD(F5-D5+180, 360)-180), 1, 0)) -> 0
B6: CircularDVF_Rigid_EC_Off_Corr_Off | C6: 1.5 | D6: 180 | E6: 0.9736869 | F6: -179.81763 | G6: -0.5263131 | H6: 0.18237322 | I6: 1 | J6: 0 | K6: =IF(J6=1, "", E6) -> 0.9736869 | L6: =IF(J6=1, "", IF(D6=90, ABS(MOD(F6-D6+180, 360)-180), ABS(IF(ABS(MOD(F6-(180-D6)+180, 360)-180) < ABS(MOD(F6-D6+180, 360)-180), MOD(F6-(180-D6)+180, 360)-180, MOD(F6-D6+180, 360)-180)))) -> 0.18237322 | M6: =IF(OR(J6=1, D6=90), 0, IF(ABS(MOD(F6-(180-D6)+180, 360)-180) < ABS(MOD(F6-D6+180, 360)-180), 1, 0)) -> 0
B7: CircularDVF_Rigid_EC_Off_Corr_Off | C7: 0.5 | D7: 180 | E7: 0.96335611 | F7: -179.81567 | G7: 0.46335611 | H7: 0.18432895 | I7: 1 | J7: 0 | K7: =IF(J7=1, "", E7) -> 0.96335611 | L7: =IF(J7=1, "", IF(D7=90, ABS(MOD(F7-D7+180, 360)-180), ABS(IF(ABS(MOD(F7-(180-D7)+180, 360)-180) < ABS(MOD(F7-D7+180, 360)-180), MOD(F7-(180-D7)+180, 360)-180, MOD(F7-D7+180, 360)-180)))) -> 0.18432895 | M7: =IF(OR(J7=1, D7=90), 0, IF(ABS(MOD(F7-(180-D7)+180, 360)-180) < ABS(MOD(F7-D7+180, 360)-180), 1, 0)) -> 0
B8: CircularDVF_Rigid_EC_Off_Corr_Off | C8: 1.5 | D8: 0 | E8: 1.0110065 | F8: 2.7527666 | G8: -0.48899345 | H8: 2.7527666 | I8: 0 | J8: 0 | K8: =IF(J8=1, "", E8) -> 1.0110065 | L8: =IF(J8=1, "", IF(D8=90, ABS(MOD(F8-D8+180, 360)-180), ABS(IF(ABS(MOD(F8-(180-D8)+180, 360)-180) < ABS(MOD(F8-D8+180, 360)-180), MOD(F8-(180-D8)+180, 360)-180, MOD(F8-D8+180, 360)-180)))) -> 2.7527666 | M8: =IF(OR(J8=1, D8=90), 0, IF(ABS(MOD(F8-(180-D8)+180, 360)-180) < ABS(MOD(F8-D8+180, 360)-180), 1, 0)) -> 0
B9: CircularDVF_Rigid_EC_Off_Corr_Off | C9: 1 | D9: 45 | E9: 0.96341981 | F9: 91.997166 | G9: -0.036580194 | H9: 46.997166 | I9: 1 | J9: 0 | K9: =IF(J9=1, "", E9) -> 0.96341981 | L9: =IF(J9=1, "", IF(D9=90, ABS(MOD(F9-D9+180, 360)-180), ABS(IF(ABS(MOD(F9-(180-D9)+180, 360)-180) < ABS(MOD(F9-D9+180, 360)-180), MOD(F9-(180-D9)+180, 360)-180, MOD(F9-D9+180, 360)-180)))) -> 43.002834 | M9: =IF(OR(J9=1, D9=90), 0, IF(ABS(MOD(F9-(180-D9)+180, 360)-180) < ABS(MOD(F9-D9+180, 360)-180), 1, 0)) -> 1
B10: CircularDVF_Rigid_EC_Off_Corr_Off | C10: 0.7 | D10: 135 | E10: 0.99453361 | F10: 56.417228 | G10: 0.29453361 | H10: -78.582772 | I10: 1 | J10: 0 | K10: =IF(J10=1, "", E10) -> 0.99453361 | L10: =IF(J10=1, "", IF(D10=90, ABS(MOD(F10-D10+180, 360)-180), ABS(IF(ABS(MOD(F10-(180-D10)+180, 360)-180) < ABS(MOD(F10-D10+180, 360)-180), MOD(F10-(180-D10)+180, 360)-180, MOD(F10-D10+180, 360)-180)))) -> 11.417228 | M10: =IF(OR(J10=1, D10=90), 0, IF(ABS(MOD(F10-(180-D10)+180, 360)-180) < ABS(MOD(F10-D10+180, 360)-180), 1, 0)) -> 1
B11: CircularDVF_Rigid_EC_Off_Corr_Off | C11: 0.35 | D11: 0 | E11: 1.0050138 | F11: 47.478699 | G11: 0.65501384 | H11: 47.478699 | I11: 0 | J11: 0 | K11: =IF(J11=1, "", E11) -> 1.0050138 | L11: =IF(J11=1, "", IF(D11=90, ABS(MOD(F11-D11+180, 360)-180), ABS(IF(ABS(MOD(F11-(180-D11)+180, 360)-180) < ABS(MOD(F11-D11+180, 360)-180), MOD(F11-(180-D11)+180, 360)-180, MOD(F11-D11+180, 360)-180)))) -> 47.478699 | M11: =IF(OR(J11=1, D11=90), 0, IF(ABS(MOD(F11-(180-D11)+180, 360)-180) < ABS(MOD(F11-D11+180, 360)-180), 1, 0)) -> 0
B12: CircularDVF_Rigid_EC_Off_Corr_Off | C12: 1.5 | D12: 180 | E12: 0.96335611 | F12: -179.81567 | G12: -0.53664389 | H12: 0.18432895 | I12: 1 | J12: 0 | K12: =IF(J12=1, "", E12) -> 0.96335611 | L12: =IF(J12=1, "", IF(D12=90, ABS(MOD(F12-D12+180, 360)-180), ABS(IF(ABS(MOD(F12-(180-D12)+180, 360)-180) < ABS(MOD(F12-D12+180, 360)-180), MOD(F12-(180-D12)+180, 360)-180, MOD(F12-D12+180, 360)-180)))) -> 0.18432895 | M12: =IF(OR(J12=1, D12=90), 0, IF(ABS(MOD(F12-(180-D12)+180, 360)-180) < ABS(MOD(F12-D12+180, 360)-180), 1, 0)) -> 0
B13: CircularDVF_Rigid_EC_Off_Corr_Off | C13: 1.5 | D13: 0 | E13: 0.9496401 | F13: 43.435172 | G13: -0.5503599 | H13: 43.435172 | I13: 0 | J13: 0 | K13: =IF(J13=1, "", E13) -> 0.9496401 | L13: =IF(J13=1, "", IF(D13=90, ABS(MOD(F13-D13+180, 360)-180), ABS(IF(ABS(MOD(F13-(180-D13)+180, 360)-180) < ABS(MOD(F13-D13+180, 360)-180), MOD(F13-(180-D13)+180, 360)-180, MOD(F13-D13+180, 360)-180)))) -> 43.435172 | M13: =IF(OR(J13=1, D13=90), 0, IF(ABS(MOD(F13-(180-D13)+180, 360)-180) < ABS(MOD(F13-D13+180, 360)-180), 1, 0)) -> 0
... B1951: CircularDVF_Rigid_EC_Off_Corr_Off | C1951: 1.5 | D1951: 0 | E1951: 0.68005693 | F1951: 2.7863412 | G1951: -0.81994307 | H1951: 2.7863412 | I1951: 0 | J1951: 0 | K1951: =IF(J1951=1, "", E1951) -> 0.68005693 | L1951: =IF(J1951=1, "", IF(D1951=90, ABS(MOD(F1951-D1951+180, 360)-180), ABS(IF(ABS(MOD(F1951-(180-D1951)+180, 360)-180) < ABS(MOD(F1951-D1951+180, 360)-180), MOD(F1951-(180-D1951)+180, 360)-180, MOD(F1951-D1951+180, 360)-180)))) -> 2.7863412 | M1951: =IF(OR(J1951=1, D1951=90), 0, IF(ABS(MOD(F1951-(180-D1951)+180, 360)-180) < ABS(MOD(F1951-D1951+180, 360)-180), 1, 0)) -> 0

Sheet D_avarage
A1: 行ラベル | B1: 平均 / 分析距離 | C1: 標準偏差 / 分析距離2 | D1: 数値の個数 / 分析距離3 | E1: 平均 / 有効角度誤差 | F1: 標準偏差 / 有効角度誤差2 | G1: 数値の個数 / 有効角度誤差3
A2: 0 | B2: 0.67900818 | C2: 0.30042412 | D2: 364 | E2: 6.7701079 | F2: 13.637342 | G2: 364
A3: 0.35 | B3: 0.74441052 | C3: 0.32324632 | D3: 72 | E3: 7.93068 | F3: 12.422017 | G3: 72
A4: 0.5 | B4: 0.68600845 | C4: 0.29984334 | D4: 76 | E4: 6.6247369 | F4: 13.256084 | G4: 76
A5: 0.7 | B5: 0.6585705 | C5: 0.30153892 | D5: 73 | E5: 7.4022253 | F5: 16.438822 | G5: 73
A6: 1 | B6: 0.69485893 | C6: 0.27598908 | D6: 71 | E6: 4.7858857 | F6: 10.569007 | G6: 71
A7: 1.5 | B7: 0.61130758 | C7: 0.28286736 | D7: 72 | E7: 7.0787499 | F7: 14.509728 | G7: 72
A8: 45 | B8: 0.88731876 | C8: 0.36967864 | D8: 390 | E8: 19.511091 | F8: 16.061801 | G8: 390
A9: 0.35 | B9: 0.86200855 | C9: 0.40288666 | D9: 78 | E9: 24.454094 | F9: 16.771261 | G9: 78
A10: 0.5 | B10: 0.90238088 | C10: 0.38850125 | D10: 78 | E10: 19.232804 | F10: 15.796782 | G10: 78
A11: 0.7 | B11: 0.90823784 | C11: 0.35619706 | D11: 78 | E11: 21.196759 | F11: 16.143463 | G11: 78
A12: 1 | B12: 0.90446399 | C12: 0.35187762 | D12: 78 | E12: 18.155053 | F12: 15.517719 | G12: 78
A13: 1.5 | B13: 0.85950256 | C13: 0.34204329 | D13: 78 | E13: 14.516747 | F13: 14.267033 | G13: 78
... A31: 1.5 | B31: 0.93921705 | C31: 0.40341141 | D31: 75 | E31: 4.2472952 | F31: 9.1074534 | G31: 75
A32: 総計 | B32: 0.90058616 | C32: 0.36692772 | D32: 1904 | E32: 9.9041468 | F32: 13.92235 | G32: 1904

Sheet E
B1: Condition | C1: TargetDist | D1: TargetAngle | E1: RespDist | F1: RespAngle | G1: ErrDist | H1: ErrAngle | I1: FBConf | J1: IsInsideHead | K1: 分析距離 | L1: 有効角度誤差 | M1: New FB
B2: CircularDVF_Rigid_EC_On_Corr_Off | C2: 1.5 | D2: 180 | E2: 1.4799975 | F2: 179.32008 | G2: -0.020002517 | H2: -0.679918 | I2: 0 | J2: 0 | K2: =IF(J2=1, "", E2) -> 1.4799975 | L2: =IF(J2=1, "", IF(D2=90, ABS(MOD(F2-D2+180, 360)-180), ABS(IF(ABS(MOD(F2-(180-D2)+180, 360)-180) < ABS(MOD(F2-D2+180, 360)-180), MOD(F2-(180-D2)+180, 360)-180, MOD(F2-D2+180, 360)-180)))) -> 0.679918 | M2: =IF(OR(J2=1, D2=90), 0, IF(ABS(MOD(F2-(180-D2)+180, 360)-180) < ABS(MOD(F2-D2+180, 360)-180), 1, 0)) -> 0
B3: CircularDVF_Rigid_EC_On_Corr_Off | C3: 0.35 | D3: 90 | E3: 0.93701103 | F3: 89.842074 | G3: 0.58701103 | H3: -0.15792622 | I3: 0 | J3: 0 | K3: =IF(J3=1, "", E3) -> 0.93701103 | L3: =IF(J3=1, "", IF(D3=90, ABS(MOD(F3-D3+180, 360)-180), ABS(IF(ABS(MOD(F3-(180-D3)+180, 360)-180) < ABS(MOD(F3-D3+180, 360)-180), MOD(F3-(180-D3)+180, 360)-180, MOD(F3-D3+180, 360)-180)))) -> 0.15792622 | M3: =IF(OR(J3=1, D3=90), 0, IF(ABS(MOD(F3-(180-D3)+180, 360)-180) < ABS(MOD(F3-D3+180, 360)-180), 1, 0)) -> 0
B4: CircularDVF_Rigid_EC_On_Corr_Off | C4: 0.7 | D4: 45 | E4: 0.8701675 | F4: 88.469301 | G4: 0.1701675 | H4: 43.469301 | I4: 0 | J4: 0 | K4: =IF(J4=1, "", E4) -> 0.8701675 | L4: =IF(J4=1, "", IF(D4=90, ABS(MOD(F4-D4+180, 360)-180), ABS(IF(ABS(MOD(F4-(180-D4)+180, 360)-180) < ABS(MOD(F4-D4+180, 360)-180), MOD(F4-(180-D4)+180, 360)-180, MOD(F4-D4+180, 360)-180)))) -> 43.469301 | M4: =IF(OR(J4=1, D4=90), 0, IF(ABS(MOD(F4-(180-D4)+180, 360)-180) < ABS(MOD(F4-D4+180, 360)-180), 1, 0)) -> 0
B5: CircularDVF_Rigid_EC_On_Corr_Off | C5: 0.7 | D5: 180 | E5: 0.98403938 | F5: 179.57894 | G5: 0.28403938 | H5: -0.42106377 | I5: 0 | J5: 0 | K5: =IF(J5=1, "", E5) -> 0.98403938 | L5: =IF(J5=1, "", IF(D5=90, ABS(MOD(F5-D5+180, 360)-180), ABS(IF(ABS(MOD(F5-(180-D5)+180, 360)-180) < ABS(MOD(F5-D5+180, 360)-180), MOD(F5-(180-D5)+180, 360)-180, MOD(F5-D5+180, 360)-180)))) -> 0.42106377 | M5: =IF(OR(J5=1, D5=90), 0, IF(ABS(MOD(F5-(180-D5)+180, 360)-180) < ABS(MOD(F5-D5+180, 360)-180), 1, 0)) -> 0
B6: CircularDVF_Rigid_EC_On_Corr_Off | C6: 0.35 | D6: 45 | E6: 0.92670902 | F6: 89.520949 | G6: 0.57670902 | H6: 44.520949 | I6: 0 | J6: 0 | K6: =IF(J6=1, "", E6) -> 0.92670902 | L6: =IF(J6=1, "", IF(D6=90, ABS(MOD(F6-D6+180, 360)-180), ABS(IF(ABS(MOD(F6-(180-D6)+180, 360)-180) < ABS(MOD(F6-D6+180, 360)-180), MOD(F6-(180-D6)+180, 360)-180, MOD(F6-D6+180, 360)-180)))) -> 44.520949 | M6: =IF(OR(J6=1, D6=90), 0, IF(ABS(MOD(F6-(180-D6)+180, 360)-180) < ABS(MOD(F6-D6+180, 360)-180), 1, 0)) -> 0
B7: CircularDVF_Rigid_EC_On_Corr_Off | C7: 0.5 | D7: 45 | E7: 0.91118402 | F7: 90.162403 | G7: 0.41118402 | H7: 45.162403 | I7: 1 | J7: 0 | K7: =IF(J7=1, "", E7) -> 0.91118402 | L7: =IF(J7=1, "", IF(D7=90, ABS(MOD(F7-D7+180, 360)-180), ABS(IF(ABS(MOD(F7-(180-D7)+180, 360)-180) < ABS(MOD(F7-D7+180, 360)-180), MOD(F7-(180-D7)+180, 360)-180, MOD(F7-D7+180, 360)-180)))) -> 44.837597 | M7: =IF(OR(J7=1, D7=90), 0, IF(ABS(MOD(F7-(180-D7)+180, 360)-180) < ABS(MOD(F7-D7+180, 360)-180), 1, 0)) -> 1
B8: CircularDVF_Rigid_EC_On_Corr_Off | C8: 0.5 | D8: 0 | E8: 0.99460336 | F8: 1.3093898 | G8: 0.49460336 | H8: 1.3093898 | I8: 0 | J8: 0 | K8: =IF(J8=1, "", E8) -> 0.99460336 | L8: =IF(J8=1, "", IF(D8=90, ABS(MOD(F8-D8+180, 360)-180), ABS(IF(ABS(MOD(F8-(180-D8)+180, 360)-180) < ABS(MOD(F8-D8+180, 360)-180), MOD(F8-(180-D8)+180, 360)-180, MOD(F8-D8+180, 360)-180)))) -> 1.3093898 | M8: =IF(OR(J8=1, D8=90), 0, IF(ABS(MOD(F8-(180-D8)+180, 360)-180) < ABS(MOD(F8-D8+180, 360)-180), 1, 0)) -> 0
B9: CircularDVF_Rigid_EC_On_Corr_Off | C9: 0.5 | D9: 45 | E9: 0.91678608 | F9: 91.775794 | G9: 0.41678608 | H9: 46.775794 | I9: 1 | J9: 0 | K9: =IF(J9=1, "", E9) -> 0.91678608 | L9: =IF(J9=1, "", IF(D9=90, ABS(MOD(F9-D9+180, 360)-180), ABS(IF(ABS(MOD(F9-(180-D9)+180, 360)-180) < ABS(MOD(F9-D9+180, 360)-180), MOD(F9-(180-D9)+180, 360)-180, MOD(F9-D9+180, 360)-180)))) -> 43.224206 | M9: =IF(OR(J9=1, D9=90), 0, IF(ABS(MOD(F9-(180-D9)+180, 360)-180) < ABS(MOD(F9-D9+180, 360)-180), 1, 0)) -> 1
B10: CircularDVF_Rigid_EC_On_Corr_Off | C10: 0.5 | D10: 90 | E10: 1.4742136 | F10: 90.100378 | G10: 0.97421358 | H10: 0.10037793 | I10: 1 | J10: 0 | K10: =IF(J10=1, "", E10) -> 1.4742136 | L10: =IF(J10=1, "", IF(D10=90, ABS(MOD(F10-D10+180, 360)-180), ABS(IF(ABS(MOD(F10-(180-D10)+180, 360)-180) < ABS(MOD(F10-D10+180, 360)-180), MOD(F10-(180-D10)+180, 360)-180, MOD(F10-D10+180, 360)-180)))) -> 0.10037793 | M10: =IF(OR(J10=1, D10=90), 0, IF(ABS(MOD(F10-(180-D10)+180, 360)-180) < ABS(MOD(F10-D10+180, 360)-180), 1, 0)) -> 0
B11: CircularDVF_Rigid_EC_On_Corr_Off | C11: 1 | D11: 45 | E11: 0.90168215 | F11: 87.537536 | G11: -0.098317852 | H11: 42.537536 | I11: 0 | J11: 0 | K11: =IF(J11=1, "", E11) -> 0.90168215 | L11: =IF(J11=1, "", IF(D11=90, ABS(MOD(F11-D11+180, 360)-180), ABS(IF(ABS(MOD(F11-(180-D11)+180, 360)-180) < ABS(MOD(F11-D11+180, 360)-180), MOD(F11-(180-D11)+180, 360)-180, MOD(F11-D11+180, 360)-180)))) -> 42.537536 | M11: =IF(OR(J11=1, D11=90), 0, IF(ABS(MOD(F11-(180-D11)+180, 360)-180) < ABS(MOD(F11-D11+180, 360)-180), 1, 0)) -> 0
B12: CircularDVF_Rigid_EC_On_Corr_Off | C12: 0.35 | D12: 90 | E12: 1.6550998 | F12: 90.625865 | G12: 1.3050998 | H12: 0.62586533 | I12: 1 | J12: 0 | K12: =IF(J12=1, "", E12) -> 1.6550998 | L12: =IF(J12=1, "", IF(D12=90, ABS(MOD(F12-D12+180, 360)-180), ABS(IF(ABS(MOD(F12-(180-D12)+180, 360)-180) < ABS(MOD(F12-D12+180, 360)-180), MOD(F12-(180-D12)+180, 360)-180, MOD(F12-D12+180, 360)-180)))) -> 0.62586533 | M12: =IF(OR(J12=1, D12=90), 0, IF(ABS(MOD(F12-(180-D12)+180, 360)-180) < ABS(MOD(F12-D12+180, 360)-180), 1, 0)) -> 0
B13: CircularDVF_Rigid_EC_On_Corr_Off | C13: 0.35 | D13: 180 | E13: 1.0006877 | F13: 177.21883 | G13: 0.65068775 | H13: -2.7811745 | I13: 0 | J13: 0 | K13: =IF(J13=1, "", E13) -> 1.0006877 | L13: =IF(J13=1, "", IF(D13=90, ABS(MOD(F13-D13+180, 360)-180), ABS(IF(ABS(MOD(F13-(180-D13)+180, 360)-180) < ABS(MOD(F13-D13+180, 360)-180), MOD(F13-(180-D13)+180, 360)-180, MOD(F13-D13+180, 360)-180)))) -> 2.7811745 | M13: =IF(OR(J13=1, D13=90), 0, IF(ABS(MOD(F13-(180-D13)+180, 360)-180) < ABS(MOD(F13-D13+180, 360)-180), 1, 0)) -> 0
... B1951: CircularDVF_Rigid_EC_On_Corr_Off | C1951: 0.5 | D1951: 180 | E1951: 1.6503987 | F1951: 179.56962 | G1951: 1.1503987 | H1951: -0.43038274 | I1951: 0 | J1951: 0 | K1951: =IF(J1951=1, "", E1951) -> 1.6503987 | L1951: =IF(J1951=1, "", IF(D1951=90, ABS(MOD(F1951-D1951+180, 360)-180), ABS(IF(ABS(MOD(F1951-(180-D1951)+180, 360)-180) < ABS(MOD(F1951-D1951+180, 360)-180), MOD(F1951-(180-D1951)+180, 360)-180, MOD(F1951-D1951+180, 360)-180)))) -> 0.43038274 | M1951: =IF(OR(J1951=1, D1951=90), 0, IF(ABS(MOD(F1951-(180-D1951)+180, 360)-180) < ABS(MOD(F1951-D1951+180, 360)-180), 1, 0)) -> 0

Sheet E_avarage
A1: 行ラベル | B1: 平均 / 分析距離 | C1: 標準偏差 / 分析距離2 | D1: 数値の個数 / 分析距離3 | E1: 平均 / 有効角度誤差 | F1: 標準偏差 / 有効角度誤差2 | G1: 数値の個数 / 有効角度誤差3
A2: 0 | B2: 0.6255828 | C2: 0.25865561 | D2: 364 | E2: 6.716646 | F2: 13.443859 | G2: 364
A3: 0.35 | B3: 0.6556386 | C3: 0.26495131 | D3: 74 | E3: 8.6243103 | F3: 16.300436 | G3: 74
A4: 0.5 | B4: 0.63900987 | C4: 0.24972953 | D4: 74 | E4: 7.5473901 | F4: 15.778016 | G4: 74
A5: 0.7 | B5: 0.60984253 | C5: 0.28459914 | D5: 73 | E5: 6.3137268 | F5: 11.55386 | G5: 73
A6: 1 | B6: 0.61577387 | C6: 0.25366318 | D6: 72 | E6: 5.2424074 | F6: 11.842 | G6: 72
A7: 1.5 | B7: 0.60639336 | C7: 0.23334396 | D7: 71 | E7: 5.7718019 | F7: 10.147187 | G7: 71
A8: 45 | B8: 0.85511943 | C8: 0.33121768 | D8: 389 | E8: 19.507168 | F8: 16.555352 | G8: 389
A9: 0.35 | B9: 0.8219344 | C9: 0.41039583 | D9: 78 | E9: 22.536478 | F9: 17.560983 | G9: 78
A10: 0.5 | B10: 0.8554283 | C10: 0.28414344 | D10: 78 | E10: 21.421412 | F10: 16.57124 | G10: 78
A11: 0.7 | B11: 0.87453954 | C11: 0.31641934 | D11: 78 | E11: 17.923698 | F11: 15.377476 | G11: 78
A12: 1 | B12: 0.8575099 | C12: 0.31525911 | D12: 78 | E12: 17.94009 | F12: 16.382115 | G12: 78
A13: 1.5 | B13: 0.86632871 | C13: 0.31320435 | D13: 77 | E13: 17.690874 | F13: 16.166004 | G13: 77
... A31: 1.5 | B31: 0.95658207 | C31: 0.38217993 | D31: 73 | E31: 5.5138445 | F31: 15.36173 | G31: 73
A32: 総計 | B32: 0.8963254 | C32: 0.35759077 | D32: 1893 | E32: 9.7768705 | F32: 14.582486 | G32: 1893

Sheet F
B1: Condition | C1: TargetDist | D1: TargetAngle | E1: RespDist | F1: RespAngle | G1: ErrDist | H1: ErrAngle | I1: FBConf | J1: IsInsideHead | K1: 分析距離 | L1: 有効角度誤差 | M1: New FB
B2: CircularDVF_Rigid_EC_On_Corr_On | C2: 0.7 | D2: 135 | E2: 0.96877492 | F2: 87.708169 | G2: 0.26877492 | H2: -47.291831 | I2: 1 | J2: 0 | K2: =IF(J2=1, "", E2) -> 0.96877492 | L2: =IF(J2=1, "", IF(D2=90, ABS(MOD(F2-D2+180, 360)-180), ABS(IF(ABS(MOD(F2-(180-D2)+180, 360)-180) < ABS(MOD(F2-D2+180, 360)-180), MOD(F2-(180-D2)+180, 360)-180, MOD(F2-D2+180, 360)-180)))) -> 42.708169 | M2: =IF(OR(J2=1, D2=90), 0, IF(ABS(MOD(F2-(180-D2)+180, 360)-180) < ABS(MOD(F2-D2+180, 360)-180), 1, 0)) -> 1
B3: CircularDVF_Rigid_EC_On_Corr_On | C3: 0.35 | D3: 90 | E3: 0.50828404 | F3: 89.708865 | G3: 0.15828404 | H3: -0.29113459 | I3: 0 | J3: 0 | K3: =IF(J3=1, "", E3) -> 0.50828404 | L3: =IF(J3=1, "", IF(D3=90, ABS(MOD(F3-D3+180, 360)-180), ABS(IF(ABS(MOD(F3-(180-D3)+180, 360)-180) < ABS(MOD(F3-D3+180, 360)-180), MOD(F3-(180-D3)+180, 360)-180, MOD(F3-D3+180, 360)-180)))) -> 0.29113459 | M3: =IF(OR(J3=1, D3=90), 0, IF(ABS(MOD(F3-(180-D3)+180, 360)-180) < ABS(MOD(F3-D3+180, 360)-180), 1, 0)) -> 0
B4: CircularDVF_Rigid_EC_On_Corr_On | C4: 0.35 | D4: 90 | E4: 0.44119504 | F4: 88.993737 | G4: 0.091195041 | H4: -1.0062627 | I4: 0 | J4: 0 | K4: =IF(J4=1, "", E4) -> 0.44119504 | L4: =IF(J4=1, "", IF(D4=90, ABS(MOD(F4-D4+180, 360)-180), ABS(IF(ABS(MOD(F4-(180-D4)+180, 360)-180) < ABS(MOD(F4-D4+180, 360)-180), MOD(F4-(180-D4)+180, 360)-180, MOD(F4-D4+180, 360)-180)))) -> 1.0062627 | M4: =IF(OR(J4=1, D4=90), 0, IF(ABS(MOD(F4-(180-D4)+180, 360)-180) < ABS(MOD(F4-D4+180, 360)-180), 1, 0)) -> 0
B5: CircularDVF_Rigid_EC_On_Corr_On | C5: 0.5 | D5: 45 | E5: 0.49860661 | F5: 129.57757 | G5: -0.0013933861 | H5: 84.577575 | I5: 1 | J5: 0 | K5: =IF(J5=1, "", E5) -> 0.49860661 | L5: =IF(J5=1, "", IF(D5=90, ABS(MOD(F5-D5+180, 360)-180), ABS(IF(ABS(MOD(F5-(180-D5)+180, 360)-180) < ABS(MOD(F5-D5+180, 360)-180), MOD(F5-(180-D5)+180, 360)-180, MOD(F5-D5+180, 360)-180)))) -> 5.4224252 | M5: =IF(OR(J5=1, D5=90), 0, IF(ABS(MOD(F5-(180-D5)+180, 360)-180) < ABS(MOD(F5-D5+180, 360)-180), 1, 0)) -> 1
B6: CircularDVF_Rigid_EC_On_Corr_On | C6: 1 | D6: 90 | E6: 1.0787375 | F6: 52.372861 | G6: 0.078737541 | H6: -37.627139 | I6: 0 | J6: 0 | K6: =IF(J6=1, "", E6) -> 1.0787375 | L6: =IF(J6=1, "", IF(D6=90, ABS(MOD(F6-D6+180, 360)-180), ABS(IF(ABS(MOD(F6-(180-D6)+180, 360)-180) < ABS(MOD(F6-D6+180, 360)-180), MOD(F6-(180-D6)+180, 360)-180, MOD(F6-D6+180, 360)-180)))) -> 37.627139 | M6: =IF(OR(J6=1, D6=90), 0, IF(ABS(MOD(F6-(180-D6)+180, 360)-180) < ABS(MOD(F6-D6+180, 360)-180), 1, 0)) -> 0
B7: CircularDVF_Rigid_EC_On_Corr_On | C7: 1.5 | D7: 135 | E7: 1.4340927 | F7: -1.7750848 | G7: -0.065907332 | H7: -136.77508 | I7: 1 | J7: 0 | K7: =IF(J7=1, "", E7) -> 1.4340927 | L7: =IF(J7=1, "", IF(D7=90, ABS(MOD(F7-D7+180, 360)-180), ABS(IF(ABS(MOD(F7-(180-D7)+180, 360)-180) < ABS(MOD(F7-D7+180, 360)-180), MOD(F7-(180-D7)+180, 360)-180, MOD(F7-D7+180, 360)-180)))) -> 46.775085 | M7: =IF(OR(J7=1, D7=90), 0, IF(ABS(MOD(F7-(180-D7)+180, 360)-180) < ABS(MOD(F7-D7+180, 360)-180), 1, 0)) -> 1
B8: CircularDVF_Rigid_EC_On_Corr_On | C8: 1 | D8: 135 | E8: 1.5006577 | F8: 0.67055682 | G8: 0.50065773 | H8: -134.32944 | I8: 1 | J8: 0 | K8: =IF(J8=1, "", E8) -> 1.5006577 | L8: =IF(J8=1, "", IF(D8=90, ABS(MOD(F8-D8+180, 360)-180), ABS(IF(ABS(MOD(F8-(180-D8)+180, 360)-180) < ABS(MOD(F8-D8+180, 360)-180), MOD(F8-(180-D8)+180, 360)-180, MOD(F8-D8+180, 360)-180)))) -> 44.329443 | M8: =IF(OR(J8=1, D8=90), 0, IF(ABS(MOD(F8-(180-D8)+180, 360)-180) < ABS(MOD(F8-D8+180, 360)-180), 1, 0)) -> 1
